[2023-08-29 19:35:37,651] {processor.py:153} INFO - Started process (PID=18715) to work on /home/felipe/extracao_dados/venv/lib/python3.9/site-packages/airflow/example_dags/example_external_task_marker_dag.py
[2023-08-29 19:35:37,654] {processor.py:641} INFO - Processing file /home/felipe/extracao_dados/venv/lib/python3.9/site-packages/airflow/example_dags/example_external_task_marker_dag.py for tasks to queue
[2023-08-29 19:35:37,658] {logging_mixin.py:115} INFO - [2023-08-29 19:35:37,657] {dagbag.py:507} INFO - Filling up the DagBag from /home/felipe/extracao_dados/venv/lib/python3.9/site-packages/airflow/example_dags/example_external_task_marker_dag.py
[2023-08-29 19:35:37,759] {processor.py:651} INFO - DAG(s) dict_keys(['example_external_task_marker_parent', 'example_external_task_marker_child']) retrieved from /home/felipe/extracao_dados/venv/lib/python3.9/site-packages/airflow/example_dags/example_external_task_marker_dag.py
[2023-08-29 19:35:38,966] {logging_mixin.py:115} INFO - [2023-08-29 19:35:38,966] {manager.py:508} INFO - Created Permission View: can delete on DAG:example_external_task_marker_parent
[2023-08-29 19:35:39,050] {logging_mixin.py:115} INFO - [2023-08-29 19:35:39,050] {manager.py:508} INFO - Created Permission View: can read on DAG:example_external_task_marker_parent
[2023-08-29 19:35:39,085] {logging_mixin.py:115} INFO - [2023-08-29 19:35:39,085] {manager.py:508} INFO - Created Permission View: can edit on DAG:example_external_task_marker_parent
[2023-08-29 19:35:39,528] {logging_mixin.py:115} INFO - [2023-08-29 19:35:39,527] {manager.py:508} INFO - Created Permission View: can delete on DAG:example_external_task_marker_child
[2023-08-29 19:35:39,637] {logging_mixin.py:115} INFO - [2023-08-29 19:35:39,636] {manager.py:508} INFO - Created Permission View: can read on DAG:example_external_task_marker_child
[2023-08-29 19:35:39,673] {logging_mixin.py:115} INFO - [2023-08-29 19:35:39,673] {manager.py:508} INFO - Created Permission View: can edit on DAG:example_external_task_marker_child
[2023-08-29 19:35:39,674] {logging_mixin.py:115} INFO - [2023-08-29 19:35:39,674] {dag.py:2379} INFO - Sync 2 DAGs
[2023-08-29 19:35:39,789] {logging_mixin.py:115} INFO - [2023-08-29 19:35:39,789] {dag.py:2398} INFO - Creating ORM DAG for example_external_task_marker_parent
[2023-08-29 19:35:39,791] {logging_mixin.py:115} INFO - [2023-08-29 19:35:39,790] {dag.py:2398} INFO - Creating ORM DAG for example_external_task_marker_child
[2023-08-29 19:35:39,916] {logging_mixin.py:115} INFO - [2023-08-29 19:35:39,916] {dag.py:2927} INFO - Setting next_dagrun for example_external_task_marker_child to None, run_after=None
[2023-08-29 19:35:39,918] {logging_mixin.py:115} INFO - [2023-08-29 19:35:39,918] {dag.py:2927} INFO - Setting next_dagrun for example_external_task_marker_parent to None, run_after=None
[2023-08-29 19:35:40,520] {logging_mixin.py:115} WARNING - /home/felipe/extracao_dados/venv/lib/python3.9/site-packages/airflow/models/dagbag.py:609 DeprecationWarning: DAG.full_filepath is deprecated in favour of fileloc
[2023-08-29 19:35:40,620] {logging_mixin.py:115} INFO - [2023-08-29 19:35:40,521] {dagbag.py:609} ERROR - Failed to write serialized DAG: /home/felipe/extracao_dados/venv/lib/python3.9/site-packages/airflow/example_dags/example_external_task_marker_dag.py
Traceback (most recent call last):
  File "/home/felipe/extracao_dados/venv/lib/python3.9/site-packages/airflow/models/dagbag.py", line 598, in _serialize_dag_capturing_errors
    dag_was_updated = SerializedDagModel.write_dag(
  File "/home/felipe/extracao_dados/venv/lib/python3.9/site-packages/airflow/utils/session.py", line 68, in wrapper
    return func(*args, **kwargs)
  File "/home/felipe/extracao_dados/venv/lib/python3.9/site-packages/airflow/models/serialized_dag.py", line 138, in write_dag
    session.query(literal(True))
  File "/home/felipe/extracao_dados/venv/lib/python3.9/site-packages/sqlalchemy/orm/query.py", line 2734, in first
    return self.limit(1)._iter().first()
  File "/home/felipe/extracao_dados/venv/lib/python3.9/site-packages/sqlalchemy/orm/query.py", line 2818, in _iter
    result = self.session.execute(
  File "/home/felipe/extracao_dados/venv/lib/python3.9/site-packages/sqlalchemy/orm/session.py", line 1669, in execute
    conn = self._connection_for_bind(bind, close_with_result=True)
  File "/home/felipe/extracao_dados/venv/lib/python3.9/site-packages/sqlalchemy/orm/session.py", line 1519, in _connection_for_bind
    return self._transaction._connection_for_bind(
  File "/home/felipe/extracao_dados/venv/lib/python3.9/site-packages/sqlalchemy/orm/session.py", line 721, in _connection_for_bind
    self._assert_active()
  File "/home/felipe/extracao_dados/venv/lib/python3.9/site-packages/sqlalchemy/orm/session.py", line 601, in _assert_active
    raise sa_exc.PendingRollbackError(
sqlalchemy.exc.PendingRollbackError: This Session's transaction has been rolled back due to a previous exception during flush. To begin a new transaction with this Session, first issue Session.rollback(). Original exception was: (sqlite3.DatabaseError) database disk image is malformed
[SQL: INSERT INTO dag_code (fileloc_hash, fileloc, last_updated, source_code) VALUES (?, ?, ?, ?)]
[parameters: (46936305197005232, '/home/felipe/extracao_dados/venv/lib/python3.9/site-packages/airflow/example_dags/example_external_task_marker_dag.py', '2023-08-29 22:35:39.928324', '#\n# Licensed to the Apache Software Foundation (ASF) under one\n# or more contributor license agreements.  See the NOTICE file\n# distributed with t ... (2954 characters truncated) ... e",\n    )\n    # [END howto_operator_external_task_sensor]\n    child_task2 = EmptyOperator(task_id="child_task2")\n    child_task1 >> child_task2\n')]
(Background on this error at: http://sqlalche.me/e/14/4xp6) (Background on this error at: http://sqlalche.me/e/14/7s2a)
[2023-08-29 19:35:40,623] {logging_mixin.py:115} INFO - [2023-08-29 19:35:40,622] {dagbag.py:609} ERROR - Failed to write serialized DAG: /home/felipe/extracao_dados/venv/lib/python3.9/site-packages/airflow/example_dags/example_external_task_marker_dag.py
Traceback (most recent call last):
  File "/home/felipe/extracao_dados/venv/lib/python3.9/site-packages/airflow/models/dagbag.py", line 598, in _serialize_dag_capturing_errors
    dag_was_updated = SerializedDagModel.write_dag(
  File "/home/felipe/extracao_dados/venv/lib/python3.9/site-packages/airflow/utils/session.py", line 68, in wrapper
    return func(*args, **kwargs)
  File "/home/felipe/extracao_dados/venv/lib/python3.9/site-packages/airflow/models/serialized_dag.py", line 138, in write_dag
    session.query(literal(True))
  File "/home/felipe/extracao_dados/venv/lib/python3.9/site-packages/sqlalchemy/orm/query.py", line 2734, in first
    return self.limit(1)._iter().first()
  File "/home/felipe/extracao_dados/venv/lib/python3.9/site-packages/sqlalchemy/orm/query.py", line 2818, in _iter
    result = self.session.execute(
  File "/home/felipe/extracao_dados/venv/lib/python3.9/site-packages/sqlalchemy/orm/session.py", line 1669, in execute
    conn = self._connection_for_bind(bind, close_with_result=True)
  File "/home/felipe/extracao_dados/venv/lib/python3.9/site-packages/sqlalchemy/orm/session.py", line 1519, in _connection_for_bind
    return self._transaction._connection_for_bind(
  File "/home/felipe/extracao_dados/venv/lib/python3.9/site-packages/sqlalchemy/orm/session.py", line 721, in _connection_for_bind
    self._assert_active()
  File "/home/felipe/extracao_dados/venv/lib/python3.9/site-packages/sqlalchemy/orm/session.py", line 601, in _assert_active
    raise sa_exc.PendingRollbackError(
sqlalchemy.exc.PendingRollbackError: This Session's transaction has been rolled back due to a previous exception during flush. To begin a new transaction with this Session, first issue Session.rollback(). Original exception was: (sqlite3.DatabaseError) database disk image is malformed
[SQL: INSERT INTO dag_code (fileloc_hash, fileloc, last_updated, source_code) VALUES (?, ?, ?, ?)]
[parameters: (46936305197005232, '/home/felipe/extracao_dados/venv/lib/python3.9/site-packages/airflow/example_dags/example_external_task_marker_dag.py', '2023-08-29 22:35:39.928324', '#\n# Licensed to the Apache Software Foundation (ASF) under one\n# or more contributor license agreements.  See the NOTICE file\n# distributed with t ... (2954 characters truncated) ... e",\n    )\n    # [END howto_operator_external_task_sensor]\n    child_task2 = EmptyOperator(task_id="child_task2")\n    child_task1 >> child_task2\n')]
(Background on this error at: http://sqlalche.me/e/14/4xp6) (Background on this error at: http://sqlalche.me/e/14/7s2a)
[2023-08-29 19:35:40,624] {logging_mixin.py:115} INFO - [2023-08-29 19:35:40,624] {dag.py:2379} INFO - Sync 2 DAGs
[2023-08-29 19:35:40,631] {processor.py:164} ERROR - Got an exception! Propagating...
Traceback (most recent call last):
  File "/home/felipe/extracao_dados/venv/lib/python3.9/site-packages/airflow/dag_processing/processor.py", line 155, in _run_file_processor
    result: Tuple[int, int] = dag_file_processor.process_file(
  File "/home/felipe/extracao_dados/venv/lib/python3.9/site-packages/airflow/utils/session.py", line 71, in wrapper
    return func(*args, session=session, **kwargs)
  File "/home/felipe/extracao_dados/venv/lib/python3.9/site-packages/airflow/dag_processing/processor.py", line 660, in process_file
    dagbag.sync_to_db()
  File "/home/felipe/extracao_dados/venv/lib/python3.9/site-packages/airflow/utils/session.py", line 71, in wrapper
    return func(*args, session=session, **kwargs)
  File "/home/felipe/extracao_dados/venv/lib/python3.9/site-packages/airflow/models/dagbag.py", line 615, in sync_to_db
    for attempt in run_with_db_retries(logger=self.log):
  File "/home/felipe/extracao_dados/venv/lib/python3.9/site-packages/tenacity/__init__.py", line 382, in __iter__
    do = self.iter(retry_state=retry_state)
  File "/home/felipe/extracao_dados/venv/lib/python3.9/site-packages/tenacity/__init__.py", line 349, in iter
    return fut.result()
  File "/usr/lib/python3.9/concurrent/futures/_base.py", line 439, in result
    return self.__get_result()
  File "/usr/lib/python3.9/concurrent/futures/_base.py", line 391, in __get_result
    raise self._exception
  File "/home/felipe/extracao_dados/venv/lib/python3.9/site-packages/airflow/models/dagbag.py", line 629, in sync_to_db
    DAG.bulk_write_to_db(self.dags.values(), session=session)
  File "/home/felipe/extracao_dados/venv/lib/python3.9/site-packages/airflow/utils/session.py", line 68, in wrapper
    return func(*args, **kwargs)
  File "/home/felipe/extracao_dados/venv/lib/python3.9/site-packages/airflow/models/dag.py", line 2387, in bulk_write_to_db
    orm_dags: List[DagModel] = with_row_locks(query, of=DagModel, session=session).all()
  File "/home/felipe/extracao_dados/venv/lib/python3.9/site-packages/sqlalchemy/orm/query.py", line 2683, in all
    return self._iter().all()
  File "/home/felipe/extracao_dados/venv/lib/python3.9/site-packages/sqlalchemy/orm/query.py", line 2818, in _iter
    result = self.session.execute(
  File "/home/felipe/extracao_dados/venv/lib/python3.9/site-packages/sqlalchemy/orm/session.py", line 1669, in execute
    conn = self._connection_for_bind(bind, close_with_result=True)
  File "/home/felipe/extracao_dados/venv/lib/python3.9/site-packages/sqlalchemy/orm/session.py", line 1519, in _connection_for_bind
    return self._transaction._connection_for_bind(
  File "/home/felipe/extracao_dados/venv/lib/python3.9/site-packages/sqlalchemy/orm/session.py", line 721, in _connection_for_bind
    self._assert_active()
  File "/home/felipe/extracao_dados/venv/lib/python3.9/site-packages/sqlalchemy/orm/session.py", line 601, in _assert_active
    raise sa_exc.PendingRollbackError(
sqlalchemy.exc.PendingRollbackError: This Session's transaction has been rolled back due to a previous exception during flush. To begin a new transaction with this Session, first issue Session.rollback(). Original exception was: (sqlite3.DatabaseError) database disk image is malformed
[SQL: INSERT INTO dag_code (fileloc_hash, fileloc, last_updated, source_code) VALUES (?, ?, ?, ?)]
[parameters: (46936305197005232, '/home/felipe/extracao_dados/venv/lib/python3.9/site-packages/airflow/example_dags/example_external_task_marker_dag.py', '2023-08-29 22:35:39.928324', '#\n# Licensed to the Apache Software Foundation (ASF) under one\n# or more contributor license agreements.  See the NOTICE file\n# distributed with t ... (2954 characters truncated) ... e",\n    )\n    # [END howto_operator_external_task_sensor]\n    child_task2 = EmptyOperator(task_id="child_task2")\n    child_task1 >> child_task2\n')]
(Background on this error at: http://sqlalche.me/e/14/4xp6) (Background on this error at: http://sqlalche.me/e/14/7s2a)
[2023-08-29 19:37:38,625] {processor.py:153} INFO - Started process (PID=19724) to work on /home/felipe/extracao_dados/venv/lib/python3.9/site-packages/airflow/example_dags/example_external_task_marker_dag.py
[2023-08-29 19:37:38,630] {processor.py:641} INFO - Processing file /home/felipe/extracao_dados/venv/lib/python3.9/site-packages/airflow/example_dags/example_external_task_marker_dag.py for tasks to queue
[2023-08-29 19:37:38,632] {logging_mixin.py:115} INFO - [2023-08-29 19:37:38,632] {dagbag.py:507} INFO - Filling up the DagBag from /home/felipe/extracao_dados/venv/lib/python3.9/site-packages/airflow/example_dags/example_external_task_marker_dag.py
[2023-08-29 19:37:38,723] {processor.py:651} INFO - DAG(s) dict_keys(['example_external_task_marker_parent', 'example_external_task_marker_child']) retrieved from /home/felipe/extracao_dados/venv/lib/python3.9/site-packages/airflow/example_dags/example_external_task_marker_dag.py
[2023-08-29 19:37:39,350] {logging_mixin.py:115} INFO - [2023-08-29 19:37:39,350] {dag.py:2379} INFO - Sync 2 DAGs
[2023-08-29 19:37:39,456] {logging_mixin.py:115} INFO - [2023-08-29 19:37:39,456] {dag.py:2398} INFO - Creating ORM DAG for example_external_task_marker_parent
[2023-08-29 19:37:39,458] {logging_mixin.py:115} INFO - [2023-08-29 19:37:39,458] {dag.py:2398} INFO - Creating ORM DAG for example_external_task_marker_child
[2023-08-29 19:37:39,638] {logging_mixin.py:115} INFO - [2023-08-29 19:37:39,638] {dag.py:2927} INFO - Setting next_dagrun for example_external_task_marker_child to None, run_after=None
[2023-08-29 19:37:39,640] {logging_mixin.py:115} INFO - [2023-08-29 19:37:39,640] {dag.py:2927} INFO - Setting next_dagrun for example_external_task_marker_parent to None, run_after=None
[2023-08-29 19:37:39,890] {logging_mixin.py:115} WARNING - /home/felipe/extracao_dados/venv/lib/python3.9/site-packages/airflow/models/dagbag.py:609 DeprecationWarning: DAG.full_filepath is deprecated in favour of fileloc
[2023-08-29 19:37:39,905] {logging_mixin.py:115} INFO - [2023-08-29 19:37:39,891] {dagbag.py:609} ERROR - Failed to write serialized DAG: /home/felipe/extracao_dados/venv/lib/python3.9/site-packages/airflow/example_dags/example_external_task_marker_dag.py
Traceback (most recent call last):
  File "/home/felipe/extracao_dados/venv/lib/python3.9/site-packages/airflow/models/dagbag.py", line 598, in _serialize_dag_capturing_errors
    dag_was_updated = SerializedDagModel.write_dag(
  File "/home/felipe/extracao_dados/venv/lib/python3.9/site-packages/airflow/utils/session.py", line 68, in wrapper
    return func(*args, **kwargs)
  File "/home/felipe/extracao_dados/venv/lib/python3.9/site-packages/airflow/models/serialized_dag.py", line 138, in write_dag
    session.query(literal(True))
  File "/home/felipe/extracao_dados/venv/lib/python3.9/site-packages/sqlalchemy/orm/query.py", line 2734, in first
    return self.limit(1)._iter().first()
  File "/home/felipe/extracao_dados/venv/lib/python3.9/site-packages/sqlalchemy/orm/query.py", line 2818, in _iter
    result = self.session.execute(
  File "/home/felipe/extracao_dados/venv/lib/python3.9/site-packages/sqlalchemy/orm/session.py", line 1669, in execute
    conn = self._connection_for_bind(bind, close_with_result=True)
  File "/home/felipe/extracao_dados/venv/lib/python3.9/site-packages/sqlalchemy/orm/session.py", line 1519, in _connection_for_bind
    return self._transaction._connection_for_bind(
  File "/home/felipe/extracao_dados/venv/lib/python3.9/site-packages/sqlalchemy/orm/session.py", line 721, in _connection_for_bind
    self._assert_active()
  File "/home/felipe/extracao_dados/venv/lib/python3.9/site-packages/sqlalchemy/orm/session.py", line 601, in _assert_active
    raise sa_exc.PendingRollbackError(
sqlalchemy.exc.PendingRollbackError: This Session's transaction has been rolled back due to a previous exception during flush. To begin a new transaction with this Session, first issue Session.rollback(). Original exception was: (sqlite3.DatabaseError) database disk image is malformed
[SQL: INSERT INTO dag_code (fileloc_hash, fileloc, last_updated, source_code) VALUES (?, ?, ?, ?)]
[parameters: (46936305197005232, '/home/felipe/extracao_dados/venv/lib/python3.9/site-packages/airflow/example_dags/example_external_task_marker_dag.py', '2023-08-29 22:37:39.648914', '#\n# Licensed to the Apache Software Foundation (ASF) under one\n# or more contributor license agreements.  See the NOTICE file\n# distributed with t ... (2954 characters truncated) ... e",\n    )\n    # [END howto_operator_external_task_sensor]\n    child_task2 = EmptyOperator(task_id="child_task2")\n    child_task1 >> child_task2\n')]
(Background on this error at: http://sqlalche.me/e/14/4xp6) (Background on this error at: http://sqlalche.me/e/14/7s2a)
[2023-08-29 19:37:39,908] {logging_mixin.py:115} INFO - [2023-08-29 19:37:39,907] {dagbag.py:609} ERROR - Failed to write serialized DAG: /home/felipe/extracao_dados/venv/lib/python3.9/site-packages/airflow/example_dags/example_external_task_marker_dag.py
Traceback (most recent call last):
  File "/home/felipe/extracao_dados/venv/lib/python3.9/site-packages/airflow/models/dagbag.py", line 598, in _serialize_dag_capturing_errors
    dag_was_updated = SerializedDagModel.write_dag(
  File "/home/felipe/extracao_dados/venv/lib/python3.9/site-packages/airflow/utils/session.py", line 68, in wrapper
    return func(*args, **kwargs)
  File "/home/felipe/extracao_dados/venv/lib/python3.9/site-packages/airflow/models/serialized_dag.py", line 138, in write_dag
    session.query(literal(True))
  File "/home/felipe/extracao_dados/venv/lib/python3.9/site-packages/sqlalchemy/orm/query.py", line 2734, in first
    return self.limit(1)._iter().first()
  File "/home/felipe/extracao_dados/venv/lib/python3.9/site-packages/sqlalchemy/orm/query.py", line 2818, in _iter
    result = self.session.execute(
  File "/home/felipe/extracao_dados/venv/lib/python3.9/site-packages/sqlalchemy/orm/session.py", line 1669, in execute
    conn = self._connection_for_bind(bind, close_with_result=True)
  File "/home/felipe/extracao_dados/venv/lib/python3.9/site-packages/sqlalchemy/orm/session.py", line 1519, in _connection_for_bind
    return self._transaction._connection_for_bind(
  File "/home/felipe/extracao_dados/venv/lib/python3.9/site-packages/sqlalchemy/orm/session.py", line 721, in _connection_for_bind
    self._assert_active()
  File "/home/felipe/extracao_dados/venv/lib/python3.9/site-packages/sqlalchemy/orm/session.py", line 601, in _assert_active
    raise sa_exc.PendingRollbackError(
sqlalchemy.exc.PendingRollbackError: This Session's transaction has been rolled back due to a previous exception during flush. To begin a new transaction with this Session, first issue Session.rollback(). Original exception was: (sqlite3.DatabaseError) database disk image is malformed
[SQL: INSERT INTO dag_code (fileloc_hash, fileloc, last_updated, source_code) VALUES (?, ?, ?, ?)]
[parameters: (46936305197005232, '/home/felipe/extracao_dados/venv/lib/python3.9/site-packages/airflow/example_dags/example_external_task_marker_dag.py', '2023-08-29 22:37:39.648914', '#\n# Licensed to the Apache Software Foundation (ASF) under one\n# or more contributor license agreements.  See the NOTICE file\n# distributed with t ... (2954 characters truncated) ... e",\n    )\n    # [END howto_operator_external_task_sensor]\n    child_task2 = EmptyOperator(task_id="child_task2")\n    child_task1 >> child_task2\n')]
(Background on this error at: http://sqlalche.me/e/14/4xp6) (Background on this error at: http://sqlalche.me/e/14/7s2a)
[2023-08-29 19:37:39,909] {logging_mixin.py:115} INFO - [2023-08-29 19:37:39,909] {dag.py:2379} INFO - Sync 2 DAGs
[2023-08-29 19:37:39,914] {processor.py:164} ERROR - Got an exception! Propagating...
Traceback (most recent call last):
  File "/home/felipe/extracao_dados/venv/lib/python3.9/site-packages/airflow/dag_processing/processor.py", line 155, in _run_file_processor
    result: Tuple[int, int] = dag_file_processor.process_file(
  File "/home/felipe/extracao_dados/venv/lib/python3.9/site-packages/airflow/utils/session.py", line 71, in wrapper
    return func(*args, session=session, **kwargs)
  File "/home/felipe/extracao_dados/venv/lib/python3.9/site-packages/airflow/dag_processing/processor.py", line 660, in process_file
    dagbag.sync_to_db()
  File "/home/felipe/extracao_dados/venv/lib/python3.9/site-packages/airflow/utils/session.py", line 71, in wrapper
    return func(*args, session=session, **kwargs)
  File "/home/felipe/extracao_dados/venv/lib/python3.9/site-packages/airflow/models/dagbag.py", line 615, in sync_to_db
    for attempt in run_with_db_retries(logger=self.log):
  File "/home/felipe/extracao_dados/venv/lib/python3.9/site-packages/tenacity/__init__.py", line 382, in __iter__
    do = self.iter(retry_state=retry_state)
  File "/home/felipe/extracao_dados/venv/lib/python3.9/site-packages/tenacity/__init__.py", line 349, in iter
    return fut.result()
  File "/usr/lib/python3.9/concurrent/futures/_base.py", line 439, in result
    return self.__get_result()
  File "/usr/lib/python3.9/concurrent/futures/_base.py", line 391, in __get_result
    raise self._exception
  File "/home/felipe/extracao_dados/venv/lib/python3.9/site-packages/airflow/models/dagbag.py", line 629, in sync_to_db
    DAG.bulk_write_to_db(self.dags.values(), session=session)
  File "/home/felipe/extracao_dados/venv/lib/python3.9/site-packages/airflow/utils/session.py", line 68, in wrapper
    return func(*args, **kwargs)
  File "/home/felipe/extracao_dados/venv/lib/python3.9/site-packages/airflow/models/dag.py", line 2387, in bulk_write_to_db
    orm_dags: List[DagModel] = with_row_locks(query, of=DagModel, session=session).all()
  File "/home/felipe/extracao_dados/venv/lib/python3.9/site-packages/sqlalchemy/orm/query.py", line 2683, in all
    return self._iter().all()
  File "/home/felipe/extracao_dados/venv/lib/python3.9/site-packages/sqlalchemy/orm/query.py", line 2818, in _iter
    result = self.session.execute(
  File "/home/felipe/extracao_dados/venv/lib/python3.9/site-packages/sqlalchemy/orm/session.py", line 1669, in execute
    conn = self._connection_for_bind(bind, close_with_result=True)
  File "/home/felipe/extracao_dados/venv/lib/python3.9/site-packages/sqlalchemy/orm/session.py", line 1519, in _connection_for_bind
    return self._transaction._connection_for_bind(
  File "/home/felipe/extracao_dados/venv/lib/python3.9/site-packages/sqlalchemy/orm/session.py", line 721, in _connection_for_bind
    self._assert_active()
  File "/home/felipe/extracao_dados/venv/lib/python3.9/site-packages/sqlalchemy/orm/session.py", line 601, in _assert_active
    raise sa_exc.PendingRollbackError(
sqlalchemy.exc.PendingRollbackError: This Session's transaction has been rolled back due to a previous exception during flush. To begin a new transaction with this Session, first issue Session.rollback(). Original exception was: (sqlite3.DatabaseError) database disk image is malformed
[SQL: INSERT INTO dag_code (fileloc_hash, fileloc, last_updated, source_code) VALUES (?, ?, ?, ?)]
[parameters: (46936305197005232, '/home/felipe/extracao_dados/venv/lib/python3.9/site-packages/airflow/example_dags/example_external_task_marker_dag.py', '2023-08-29 22:37:39.648914', '#\n# Licensed to the Apache Software Foundation (ASF) under one\n# or more contributor license agreements.  See the NOTICE file\n# distributed with t ... (2954 characters truncated) ... e",\n    )\n    # [END howto_operator_external_task_sensor]\n    child_task2 = EmptyOperator(task_id="child_task2")\n    child_task1 >> child_task2\n')]
(Background on this error at: http://sqlalche.me/e/14/4xp6) (Background on this error at: http://sqlalche.me/e/14/7s2a)
