[2023-08-29 19:34:45,534] {processor.py:153} INFO - Started process (PID=18188) to work on /home/felipe/extracao_dados/venv/lib/python3.9/site-packages/airflow/example_dags/example_subdag_operator.py
[2023-08-29 19:34:45,537] {processor.py:641} INFO - Processing file /home/felipe/extracao_dados/venv/lib/python3.9/site-packages/airflow/example_dags/example_subdag_operator.py for tasks to queue
[2023-08-29 19:34:45,539] {logging_mixin.py:115} INFO - [2023-08-29 19:34:45,539] {dagbag.py:507} INFO - Filling up the DagBag from /home/felipe/extracao_dados/venv/lib/python3.9/site-packages/airflow/example_dags/example_subdag_operator.py
[2023-08-29 19:34:46,404] {processor.py:651} INFO - DAG(s) dict_keys(['example_subdag_operator.section-1', 'example_subdag_operator.section-2', 'example_subdag_operator']) retrieved from /home/felipe/extracao_dados/venv/lib/python3.9/site-packages/airflow/example_dags/example_subdag_operator.py
[2023-08-29 19:34:48,845] {logging_mixin.py:115} INFO - [2023-08-29 19:34:48,844] {manager.py:508} INFO - Created Permission View: can delete on DAG:example_subdag_operator
[2023-08-29 19:34:49,232] {logging_mixin.py:115} INFO - [2023-08-29 19:34:49,232] {manager.py:508} INFO - Created Permission View: can read on DAG:example_subdag_operator
[2023-08-29 19:34:49,727] {logging_mixin.py:115} INFO - [2023-08-29 19:34:49,727] {manager.py:508} INFO - Created Permission View: can edit on DAG:example_subdag_operator
[2023-08-29 19:34:49,728] {logging_mixin.py:115} INFO - [2023-08-29 19:34:49,728] {dag.py:2379} INFO - Sync 3 DAGs
[2023-08-29 19:34:49,877] {logging_mixin.py:115} INFO - [2023-08-29 19:34:49,877] {dag.py:2398} INFO - Creating ORM DAG for example_subdag_operator
[2023-08-29 19:34:49,879] {logging_mixin.py:115} INFO - [2023-08-29 19:34:49,879] {dag.py:2398} INFO - Creating ORM DAG for example_subdag_operator.section-2
[2023-08-29 19:34:49,880] {logging_mixin.py:115} INFO - [2023-08-29 19:34:49,880] {dag.py:2398} INFO - Creating ORM DAG for example_subdag_operator.section-1
[2023-08-29 19:34:50,151] {logging_mixin.py:115} INFO - [2023-08-29 19:34:50,150] {dag.py:2927} INFO - Setting next_dagrun for example_subdag_operator to 2022-01-01T00:00:00+00:00, run_after=2022-01-01T00:00:00+00:00
[2023-08-29 19:34:50,153] {logging_mixin.py:115} INFO - [2023-08-29 19:34:50,152] {dag.py:2927} INFO - Setting next_dagrun for example_subdag_operator.section-1 to None, run_after=None
[2023-08-29 19:34:50,153] {logging_mixin.py:115} INFO - [2023-08-29 19:34:50,153] {dag.py:2927} INFO - Setting next_dagrun for example_subdag_operator.section-2 to None, run_after=None
[2023-08-29 19:34:50,942] {logging_mixin.py:115} WARNING - /home/felipe/extracao_dados/venv/lib/python3.9/site-packages/airflow/models/dagbag.py:609 DeprecationWarning: DAG.full_filepath is deprecated in favour of fileloc
[2023-08-29 19:34:51,001] {logging_mixin.py:115} INFO - [2023-08-29 19:34:50,943] {dagbag.py:609} ERROR - Failed to write serialized DAG: /home/felipe/extracao_dados/venv/lib/python3.9/site-packages/airflow/example_dags/example_subdag_operator.py
Traceback (most recent call last):
  File "/home/felipe/extracao_dados/venv/lib/python3.9/site-packages/airflow/models/dagbag.py", line 598, in _serialize_dag_capturing_errors
    dag_was_updated = SerializedDagModel.write_dag(
  File "/home/felipe/extracao_dados/venv/lib/python3.9/site-packages/airflow/utils/session.py", line 68, in wrapper
    return func(*args, **kwargs)
  File "/home/felipe/extracao_dados/venv/lib/python3.9/site-packages/airflow/models/serialized_dag.py", line 138, in write_dag
    session.query(literal(True))
  File "/home/felipe/extracao_dados/venv/lib/python3.9/site-packages/sqlalchemy/orm/query.py", line 2734, in first
    return self.limit(1)._iter().first()
  File "/home/felipe/extracao_dados/venv/lib/python3.9/site-packages/sqlalchemy/orm/query.py", line 2818, in _iter
    result = self.session.execute(
  File "/home/felipe/extracao_dados/venv/lib/python3.9/site-packages/sqlalchemy/orm/session.py", line 1669, in execute
    conn = self._connection_for_bind(bind, close_with_result=True)
  File "/home/felipe/extracao_dados/venv/lib/python3.9/site-packages/sqlalchemy/orm/session.py", line 1519, in _connection_for_bind
    return self._transaction._connection_for_bind(
  File "/home/felipe/extracao_dados/venv/lib/python3.9/site-packages/sqlalchemy/orm/session.py", line 721, in _connection_for_bind
    self._assert_active()
  File "/home/felipe/extracao_dados/venv/lib/python3.9/site-packages/sqlalchemy/orm/session.py", line 601, in _assert_active
    raise sa_exc.PendingRollbackError(
sqlalchemy.exc.PendingRollbackError: This Session's transaction has been rolled back due to a previous exception during flush. To begin a new transaction with this Session, first issue Session.rollback(). Original exception was: (sqlite3.DatabaseError) database disk image is malformed
[SQL: INSERT INTO dag_code (fileloc_hash, fileloc, last_updated, source_code) VALUES (?, ?, ?, ?)]
[parameters: (14553882975764144, '/home/felipe/extracao_dados/venv/lib/python3.9/site-packages/airflow/example_dags/example_subdag_operator.py', '2023-08-29 22:34:50.164770', '#\n# Licensed to the Apache Software Foundation (ASF) under one\n# or more contributor license agreements.  See the NOTICE file\n# distributed with t ... (1632 characters truncated) ... = EmptyOperator(\n        task_id=\'end\',\n    )\n\n    start >> section_1 >> some_other_task >> section_2 >> end\n# [END example_subdag_operator]\n')]
(Background on this error at: http://sqlalche.me/e/14/4xp6) (Background on this error at: http://sqlalche.me/e/14/7s2a)
[2023-08-29 19:34:51,002] {logging_mixin.py:115} INFO - [2023-08-29 19:34:51,002] {dag.py:2379} INFO - Sync 3 DAGs
[2023-08-29 19:34:51,004] {processor.py:164} ERROR - Got an exception! Propagating...
Traceback (most recent call last):
  File "/home/felipe/extracao_dados/venv/lib/python3.9/site-packages/airflow/dag_processing/processor.py", line 155, in _run_file_processor
    result: Tuple[int, int] = dag_file_processor.process_file(
  File "/home/felipe/extracao_dados/venv/lib/python3.9/site-packages/airflow/utils/session.py", line 71, in wrapper
    return func(*args, session=session, **kwargs)
  File "/home/felipe/extracao_dados/venv/lib/python3.9/site-packages/airflow/dag_processing/processor.py", line 660, in process_file
    dagbag.sync_to_db()
  File "/home/felipe/extracao_dados/venv/lib/python3.9/site-packages/airflow/utils/session.py", line 71, in wrapper
    return func(*args, session=session, **kwargs)
  File "/home/felipe/extracao_dados/venv/lib/python3.9/site-packages/airflow/models/dagbag.py", line 615, in sync_to_db
    for attempt in run_with_db_retries(logger=self.log):
  File "/home/felipe/extracao_dados/venv/lib/python3.9/site-packages/tenacity/__init__.py", line 382, in __iter__
    do = self.iter(retry_state=retry_state)
  File "/home/felipe/extracao_dados/venv/lib/python3.9/site-packages/tenacity/__init__.py", line 349, in iter
    return fut.result()
  File "/usr/lib/python3.9/concurrent/futures/_base.py", line 439, in result
    return self.__get_result()
  File "/usr/lib/python3.9/concurrent/futures/_base.py", line 391, in __get_result
    raise self._exception
  File "/home/felipe/extracao_dados/venv/lib/python3.9/site-packages/airflow/models/dagbag.py", line 629, in sync_to_db
    DAG.bulk_write_to_db(self.dags.values(), session=session)
  File "/home/felipe/extracao_dados/venv/lib/python3.9/site-packages/airflow/utils/session.py", line 68, in wrapper
    return func(*args, **kwargs)
  File "/home/felipe/extracao_dados/venv/lib/python3.9/site-packages/airflow/models/dag.py", line 2387, in bulk_write_to_db
    orm_dags: List[DagModel] = with_row_locks(query, of=DagModel, session=session).all()
  File "/home/felipe/extracao_dados/venv/lib/python3.9/site-packages/sqlalchemy/orm/query.py", line 2683, in all
    return self._iter().all()
  File "/home/felipe/extracao_dados/venv/lib/python3.9/site-packages/sqlalchemy/orm/query.py", line 2818, in _iter
    result = self.session.execute(
  File "/home/felipe/extracao_dados/venv/lib/python3.9/site-packages/sqlalchemy/orm/session.py", line 1669, in execute
    conn = self._connection_for_bind(bind, close_with_result=True)
  File "/home/felipe/extracao_dados/venv/lib/python3.9/site-packages/sqlalchemy/orm/session.py", line 1519, in _connection_for_bind
    return self._transaction._connection_for_bind(
  File "/home/felipe/extracao_dados/venv/lib/python3.9/site-packages/sqlalchemy/orm/session.py", line 721, in _connection_for_bind
    self._assert_active()
  File "/home/felipe/extracao_dados/venv/lib/python3.9/site-packages/sqlalchemy/orm/session.py", line 601, in _assert_active
    raise sa_exc.PendingRollbackError(
sqlalchemy.exc.PendingRollbackError: This Session's transaction has been rolled back due to a previous exception during flush. To begin a new transaction with this Session, first issue Session.rollback(). Original exception was: (sqlite3.DatabaseError) database disk image is malformed
[SQL: INSERT INTO dag_code (fileloc_hash, fileloc, last_updated, source_code) VALUES (?, ?, ?, ?)]
[parameters: (14553882975764144, '/home/felipe/extracao_dados/venv/lib/python3.9/site-packages/airflow/example_dags/example_subdag_operator.py', '2023-08-29 22:34:50.164770', '#\n# Licensed to the Apache Software Foundation (ASF) under one\n# or more contributor license agreements.  See the NOTICE file\n# distributed with t ... (1632 characters truncated) ... = EmptyOperator(\n        task_id=\'end\',\n    )\n\n    start >> section_1 >> some_other_task >> section_2 >> end\n# [END example_subdag_operator]\n')]
(Background on this error at: http://sqlalche.me/e/14/4xp6) (Background on this error at: http://sqlalche.me/e/14/7s2a)
[2023-08-29 19:37:02,012] {processor.py:153} INFO - Started process (PID=19433) to work on /home/felipe/extracao_dados/venv/lib/python3.9/site-packages/airflow/example_dags/example_subdag_operator.py
[2023-08-29 19:37:02,014] {processor.py:641} INFO - Processing file /home/felipe/extracao_dados/venv/lib/python3.9/site-packages/airflow/example_dags/example_subdag_operator.py for tasks to queue
[2023-08-29 19:37:02,016] {logging_mixin.py:115} INFO - [2023-08-29 19:37:02,016] {dagbag.py:507} INFO - Filling up the DagBag from /home/felipe/extracao_dados/venv/lib/python3.9/site-packages/airflow/example_dags/example_subdag_operator.py
[2023-08-29 19:37:02,313] {processor.py:651} INFO - DAG(s) dict_keys(['example_subdag_operator.section-1', 'example_subdag_operator.section-2', 'example_subdag_operator']) retrieved from /home/felipe/extracao_dados/venv/lib/python3.9/site-packages/airflow/example_dags/example_subdag_operator.py
[2023-08-29 19:37:02,735] {logging_mixin.py:115} INFO - [2023-08-29 19:37:02,735] {dag.py:2379} INFO - Sync 3 DAGs
[2023-08-29 19:37:02,845] {logging_mixin.py:115} INFO - [2023-08-29 19:37:02,845] {dag.py:2398} INFO - Creating ORM DAG for example_subdag_operator
[2023-08-29 19:37:02,846] {logging_mixin.py:115} INFO - [2023-08-29 19:37:02,846] {dag.py:2398} INFO - Creating ORM DAG for example_subdag_operator.section-2
[2023-08-29 19:37:02,848] {logging_mixin.py:115} INFO - [2023-08-29 19:37:02,847] {dag.py:2398} INFO - Creating ORM DAG for example_subdag_operator.section-1
[2023-08-29 19:37:02,967] {logging_mixin.py:115} INFO - [2023-08-29 19:37:02,966] {dag.py:2927} INFO - Setting next_dagrun for example_subdag_operator to 2022-01-01T00:00:00+00:00, run_after=2022-01-01T00:00:00+00:00
[2023-08-29 19:37:02,969] {logging_mixin.py:115} INFO - [2023-08-29 19:37:02,969] {dag.py:2927} INFO - Setting next_dagrun for example_subdag_operator.section-1 to None, run_after=None
[2023-08-29 19:37:02,970] {logging_mixin.py:115} INFO - [2023-08-29 19:37:02,969] {dag.py:2927} INFO - Setting next_dagrun for example_subdag_operator.section-2 to None, run_after=None
[2023-08-29 19:37:03,563] {logging_mixin.py:115} WARNING - /home/felipe/extracao_dados/venv/lib/python3.9/site-packages/airflow/models/dagbag.py:609 DeprecationWarning: DAG.full_filepath is deprecated in favour of fileloc
[2023-08-29 19:37:03,651] {logging_mixin.py:115} INFO - [2023-08-29 19:37:03,564] {dagbag.py:609} ERROR - Failed to write serialized DAG: /home/felipe/extracao_dados/venv/lib/python3.9/site-packages/airflow/example_dags/example_subdag_operator.py
Traceback (most recent call last):
  File "/home/felipe/extracao_dados/venv/lib/python3.9/site-packages/airflow/models/dagbag.py", line 598, in _serialize_dag_capturing_errors
    dag_was_updated = SerializedDagModel.write_dag(
  File "/home/felipe/extracao_dados/venv/lib/python3.9/site-packages/airflow/utils/session.py", line 68, in wrapper
    return func(*args, **kwargs)
  File "/home/felipe/extracao_dados/venv/lib/python3.9/site-packages/airflow/models/serialized_dag.py", line 138, in write_dag
    session.query(literal(True))
  File "/home/felipe/extracao_dados/venv/lib/python3.9/site-packages/sqlalchemy/orm/query.py", line 2734, in first
    return self.limit(1)._iter().first()
  File "/home/felipe/extracao_dados/venv/lib/python3.9/site-packages/sqlalchemy/orm/query.py", line 2818, in _iter
    result = self.session.execute(
  File "/home/felipe/extracao_dados/venv/lib/python3.9/site-packages/sqlalchemy/orm/session.py", line 1669, in execute
    conn = self._connection_for_bind(bind, close_with_result=True)
  File "/home/felipe/extracao_dados/venv/lib/python3.9/site-packages/sqlalchemy/orm/session.py", line 1519, in _connection_for_bind
    return self._transaction._connection_for_bind(
  File "/home/felipe/extracao_dados/venv/lib/python3.9/site-packages/sqlalchemy/orm/session.py", line 721, in _connection_for_bind
    self._assert_active()
  File "/home/felipe/extracao_dados/venv/lib/python3.9/site-packages/sqlalchemy/orm/session.py", line 601, in _assert_active
    raise sa_exc.PendingRollbackError(
sqlalchemy.exc.PendingRollbackError: This Session's transaction has been rolled back due to a previous exception during flush. To begin a new transaction with this Session, first issue Session.rollback(). Original exception was: (sqlite3.DatabaseError) database disk image is malformed
[SQL: INSERT INTO dag_code (fileloc_hash, fileloc, last_updated, source_code) VALUES (?, ?, ?, ?)]
[parameters: (14553882975764144, '/home/felipe/extracao_dados/venv/lib/python3.9/site-packages/airflow/example_dags/example_subdag_operator.py', '2023-08-29 22:37:03.044014', '#\n# Licensed to the Apache Software Foundation (ASF) under one\n# or more contributor license agreements.  See the NOTICE file\n# distributed with t ... (1632 characters truncated) ... = EmptyOperator(\n        task_id=\'end\',\n    )\n\n    start >> section_1 >> some_other_task >> section_2 >> end\n# [END example_subdag_operator]\n')]
(Background on this error at: http://sqlalche.me/e/14/4xp6) (Background on this error at: http://sqlalche.me/e/14/7s2a)
[2023-08-29 19:37:03,652] {logging_mixin.py:115} INFO - [2023-08-29 19:37:03,652] {dag.py:2379} INFO - Sync 3 DAGs
[2023-08-29 19:37:03,656] {processor.py:164} ERROR - Got an exception! Propagating...
Traceback (most recent call last):
  File "/home/felipe/extracao_dados/venv/lib/python3.9/site-packages/airflow/dag_processing/processor.py", line 155, in _run_file_processor
    result: Tuple[int, int] = dag_file_processor.process_file(
  File "/home/felipe/extracao_dados/venv/lib/python3.9/site-packages/airflow/utils/session.py", line 71, in wrapper
    return func(*args, session=session, **kwargs)
  File "/home/felipe/extracao_dados/venv/lib/python3.9/site-packages/airflow/dag_processing/processor.py", line 660, in process_file
    dagbag.sync_to_db()
  File "/home/felipe/extracao_dados/venv/lib/python3.9/site-packages/airflow/utils/session.py", line 71, in wrapper
    return func(*args, session=session, **kwargs)
  File "/home/felipe/extracao_dados/venv/lib/python3.9/site-packages/airflow/models/dagbag.py", line 615, in sync_to_db
    for attempt in run_with_db_retries(logger=self.log):
  File "/home/felipe/extracao_dados/venv/lib/python3.9/site-packages/tenacity/__init__.py", line 382, in __iter__
    do = self.iter(retry_state=retry_state)
  File "/home/felipe/extracao_dados/venv/lib/python3.9/site-packages/tenacity/__init__.py", line 349, in iter
    return fut.result()
  File "/usr/lib/python3.9/concurrent/futures/_base.py", line 439, in result
    return self.__get_result()
  File "/usr/lib/python3.9/concurrent/futures/_base.py", line 391, in __get_result
    raise self._exception
  File "/home/felipe/extracao_dados/venv/lib/python3.9/site-packages/airflow/models/dagbag.py", line 629, in sync_to_db
    DAG.bulk_write_to_db(self.dags.values(), session=session)
  File "/home/felipe/extracao_dados/venv/lib/python3.9/site-packages/airflow/utils/session.py", line 68, in wrapper
    return func(*args, **kwargs)
  File "/home/felipe/extracao_dados/venv/lib/python3.9/site-packages/airflow/models/dag.py", line 2387, in bulk_write_to_db
    orm_dags: List[DagModel] = with_row_locks(query, of=DagModel, session=session).all()
  File "/home/felipe/extracao_dados/venv/lib/python3.9/site-packages/sqlalchemy/orm/query.py", line 2683, in all
    return self._iter().all()
  File "/home/felipe/extracao_dados/venv/lib/python3.9/site-packages/sqlalchemy/orm/query.py", line 2818, in _iter
    result = self.session.execute(
  File "/home/felipe/extracao_dados/venv/lib/python3.9/site-packages/sqlalchemy/orm/session.py", line 1669, in execute
    conn = self._connection_for_bind(bind, close_with_result=True)
  File "/home/felipe/extracao_dados/venv/lib/python3.9/site-packages/sqlalchemy/orm/session.py", line 1519, in _connection_for_bind
    return self._transaction._connection_for_bind(
  File "/home/felipe/extracao_dados/venv/lib/python3.9/site-packages/sqlalchemy/orm/session.py", line 721, in _connection_for_bind
    self._assert_active()
  File "/home/felipe/extracao_dados/venv/lib/python3.9/site-packages/sqlalchemy/orm/session.py", line 601, in _assert_active
    raise sa_exc.PendingRollbackError(
sqlalchemy.exc.PendingRollbackError: This Session's transaction has been rolled back due to a previous exception during flush. To begin a new transaction with this Session, first issue Session.rollback(). Original exception was: (sqlite3.DatabaseError) database disk image is malformed
[SQL: INSERT INTO dag_code (fileloc_hash, fileloc, last_updated, source_code) VALUES (?, ?, ?, ?)]
[parameters: (14553882975764144, '/home/felipe/extracao_dados/venv/lib/python3.9/site-packages/airflow/example_dags/example_subdag_operator.py', '2023-08-29 22:37:03.044014', '#\n# Licensed to the Apache Software Foundation (ASF) under one\n# or more contributor license agreements.  See the NOTICE file\n# distributed with t ... (1632 characters truncated) ... = EmptyOperator(\n        task_id=\'end\',\n    )\n\n    start >> section_1 >> some_other_task >> section_2 >> end\n# [END example_subdag_operator]\n')]
(Background on this error at: http://sqlalche.me/e/14/4xp6) (Background on this error at: http://sqlalche.me/e/14/7s2a)
[2023-08-29 19:38:27,340] {processor.py:153} INFO - Started process (PID=20109) to work on /home/felipe/extracao_dados/venv/lib/python3.9/site-packages/airflow/example_dags/example_subdag_operator.py
[2023-08-29 19:38:27,343] {processor.py:641} INFO - Processing file /home/felipe/extracao_dados/venv/lib/python3.9/site-packages/airflow/example_dags/example_subdag_operator.py for tasks to queue
[2023-08-29 19:38:27,345] {logging_mixin.py:115} INFO - [2023-08-29 19:38:27,344] {dagbag.py:507} INFO - Filling up the DagBag from /home/felipe/extracao_dados/venv/lib/python3.9/site-packages/airflow/example_dags/example_subdag_operator.py
[2023-08-29 19:38:27,830] {processor.py:651} INFO - DAG(s) dict_keys(['example_subdag_operator.section-1', 'example_subdag_operator.section-2', 'example_subdag_operator']) retrieved from /home/felipe/extracao_dados/venv/lib/python3.9/site-packages/airflow/example_dags/example_subdag_operator.py
[2023-08-29 19:38:28,152] {logging_mixin.py:115} INFO - [2023-08-29 19:38:28,152] {dag.py:2379} INFO - Sync 3 DAGs
[2023-08-29 19:38:28,275] {logging_mixin.py:115} INFO - [2023-08-29 19:38:28,274] {dag.py:2398} INFO - Creating ORM DAG for example_subdag_operator
[2023-08-29 19:38:28,340] {logging_mixin.py:115} INFO - [2023-08-29 19:38:28,340] {dag.py:2398} INFO - Creating ORM DAG for example_subdag_operator.section-2
[2023-08-29 19:38:28,341] {logging_mixin.py:115} INFO - [2023-08-29 19:38:28,341] {dag.py:2398} INFO - Creating ORM DAG for example_subdag_operator.section-1
[2023-08-29 19:38:28,452] {logging_mixin.py:115} INFO - [2023-08-29 19:38:28,452] {dag.py:2927} INFO - Setting next_dagrun for example_subdag_operator to 2022-01-01T00:00:00+00:00, run_after=2022-01-01T00:00:00+00:00
[2023-08-29 19:38:28,454] {logging_mixin.py:115} INFO - [2023-08-29 19:38:28,454] {dag.py:2927} INFO - Setting next_dagrun for example_subdag_operator.section-1 to None, run_after=None
[2023-08-29 19:38:28,455] {logging_mixin.py:115} INFO - [2023-08-29 19:38:28,455] {dag.py:2927} INFO - Setting next_dagrun for example_subdag_operator.section-2 to None, run_after=None
[2023-08-29 19:38:28,736] {logging_mixin.py:115} WARNING - /home/felipe/extracao_dados/venv/lib/python3.9/site-packages/airflow/models/dagbag.py:609 DeprecationWarning: DAG.full_filepath is deprecated in favour of fileloc
[2023-08-29 19:38:28,746] {logging_mixin.py:115} INFO - [2023-08-29 19:38:28,736] {dagbag.py:609} ERROR - Failed to write serialized DAG: /home/felipe/extracao_dados/venv/lib/python3.9/site-packages/airflow/example_dags/example_subdag_operator.py
Traceback (most recent call last):
  File "/home/felipe/extracao_dados/venv/lib/python3.9/site-packages/airflow/models/dagbag.py", line 598, in _serialize_dag_capturing_errors
    dag_was_updated = SerializedDagModel.write_dag(
  File "/home/felipe/extracao_dados/venv/lib/python3.9/site-packages/airflow/utils/session.py", line 68, in wrapper
    return func(*args, **kwargs)
  File "/home/felipe/extracao_dados/venv/lib/python3.9/site-packages/airflow/models/serialized_dag.py", line 138, in write_dag
    session.query(literal(True))
  File "/home/felipe/extracao_dados/venv/lib/python3.9/site-packages/sqlalchemy/orm/query.py", line 2734, in first
    return self.limit(1)._iter().first()
  File "/home/felipe/extracao_dados/venv/lib/python3.9/site-packages/sqlalchemy/orm/query.py", line 2818, in _iter
    result = self.session.execute(
  File "/home/felipe/extracao_dados/venv/lib/python3.9/site-packages/sqlalchemy/orm/session.py", line 1669, in execute
    conn = self._connection_for_bind(bind, close_with_result=True)
  File "/home/felipe/extracao_dados/venv/lib/python3.9/site-packages/sqlalchemy/orm/session.py", line 1519, in _connection_for_bind
    return self._transaction._connection_for_bind(
  File "/home/felipe/extracao_dados/venv/lib/python3.9/site-packages/sqlalchemy/orm/session.py", line 721, in _connection_for_bind
    self._assert_active()
  File "/home/felipe/extracao_dados/venv/lib/python3.9/site-packages/sqlalchemy/orm/session.py", line 601, in _assert_active
    raise sa_exc.PendingRollbackError(
sqlalchemy.exc.PendingRollbackError: This Session's transaction has been rolled back due to a previous exception during flush. To begin a new transaction with this Session, first issue Session.rollback(). Original exception was: (sqlite3.DatabaseError) database disk image is malformed
[SQL: INSERT INTO dag_code (fileloc_hash, fileloc, last_updated, source_code) VALUES (?, ?, ?, ?)]
[parameters: (14553882975764144, '/home/felipe/extracao_dados/venv/lib/python3.9/site-packages/airflow/example_dags/example_subdag_operator.py', '2023-08-29 22:38:28.462384', '#\n# Licensed to the Apache Software Foundation (ASF) under one\n# or more contributor license agreements.  See the NOTICE file\n# distributed with t ... (1632 characters truncated) ... = EmptyOperator(\n        task_id=\'end\',\n    )\n\n    start >> section_1 >> some_other_task >> section_2 >> end\n# [END example_subdag_operator]\n')]
(Background on this error at: http://sqlalche.me/e/14/4xp6) (Background on this error at: http://sqlalche.me/e/14/7s2a)
[2023-08-29 19:38:28,746] {logging_mixin.py:115} INFO - [2023-08-29 19:38:28,746] {dag.py:2379} INFO - Sync 3 DAGs
[2023-08-29 19:38:28,751] {processor.py:164} ERROR - Got an exception! Propagating...
Traceback (most recent call last):
  File "/home/felipe/extracao_dados/venv/lib/python3.9/site-packages/airflow/dag_processing/processor.py", line 155, in _run_file_processor
    result: Tuple[int, int] = dag_file_processor.process_file(
  File "/home/felipe/extracao_dados/venv/lib/python3.9/site-packages/airflow/utils/session.py", line 71, in wrapper
    return func(*args, session=session, **kwargs)
  File "/home/felipe/extracao_dados/venv/lib/python3.9/site-packages/airflow/dag_processing/processor.py", line 660, in process_file
    dagbag.sync_to_db()
  File "/home/felipe/extracao_dados/venv/lib/python3.9/site-packages/airflow/utils/session.py", line 71, in wrapper
    return func(*args, session=session, **kwargs)
  File "/home/felipe/extracao_dados/venv/lib/python3.9/site-packages/airflow/models/dagbag.py", line 615, in sync_to_db
    for attempt in run_with_db_retries(logger=self.log):
  File "/home/felipe/extracao_dados/venv/lib/python3.9/site-packages/tenacity/__init__.py", line 382, in __iter__
    do = self.iter(retry_state=retry_state)
  File "/home/felipe/extracao_dados/venv/lib/python3.9/site-packages/tenacity/__init__.py", line 349, in iter
    return fut.result()
  File "/usr/lib/python3.9/concurrent/futures/_base.py", line 439, in result
    return self.__get_result()
  File "/usr/lib/python3.9/concurrent/futures/_base.py", line 391, in __get_result
    raise self._exception
  File "/home/felipe/extracao_dados/venv/lib/python3.9/site-packages/airflow/models/dagbag.py", line 629, in sync_to_db
    DAG.bulk_write_to_db(self.dags.values(), session=session)
  File "/home/felipe/extracao_dados/venv/lib/python3.9/site-packages/airflow/utils/session.py", line 68, in wrapper
    return func(*args, **kwargs)
  File "/home/felipe/extracao_dados/venv/lib/python3.9/site-packages/airflow/models/dag.py", line 2387, in bulk_write_to_db
    orm_dags: List[DagModel] = with_row_locks(query, of=DagModel, session=session).all()
  File "/home/felipe/extracao_dados/venv/lib/python3.9/site-packages/sqlalchemy/orm/query.py", line 2683, in all
    return self._iter().all()
  File "/home/felipe/extracao_dados/venv/lib/python3.9/site-packages/sqlalchemy/orm/query.py", line 2818, in _iter
    result = self.session.execute(
  File "/home/felipe/extracao_dados/venv/lib/python3.9/site-packages/sqlalchemy/orm/session.py", line 1669, in execute
    conn = self._connection_for_bind(bind, close_with_result=True)
  File "/home/felipe/extracao_dados/venv/lib/python3.9/site-packages/sqlalchemy/orm/session.py", line 1519, in _connection_for_bind
    return self._transaction._connection_for_bind(
  File "/home/felipe/extracao_dados/venv/lib/python3.9/site-packages/sqlalchemy/orm/session.py", line 721, in _connection_for_bind
    self._assert_active()
  File "/home/felipe/extracao_dados/venv/lib/python3.9/site-packages/sqlalchemy/orm/session.py", line 601, in _assert_active
    raise sa_exc.PendingRollbackError(
sqlalchemy.exc.PendingRollbackError: This Session's transaction has been rolled back due to a previous exception during flush. To begin a new transaction with this Session, first issue Session.rollback(). Original exception was: (sqlite3.DatabaseError) database disk image is malformed
[SQL: INSERT INTO dag_code (fileloc_hash, fileloc, last_updated, source_code) VALUES (?, ?, ?, ?)]
[parameters: (14553882975764144, '/home/felipe/extracao_dados/venv/lib/python3.9/site-packages/airflow/example_dags/example_subdag_operator.py', '2023-08-29 22:38:28.462384', '#\n# Licensed to the Apache Software Foundation (ASF) under one\n# or more contributor license agreements.  See the NOTICE file\n# distributed with t ... (1632 characters truncated) ... = EmptyOperator(\n        task_id=\'end\',\n    )\n\n    start >> section_1 >> some_other_task >> section_2 >> end\n# [END example_subdag_operator]\n')]
(Background on this error at: http://sqlalche.me/e/14/4xp6) (Background on this error at: http://sqlalche.me/e/14/7s2a)
