[2023-08-29 19:36:09,332] {processor.py:153} INFO - Started process (PID=18963) to work on /home/felipe/extracao_dados/venv/lib/python3.9/site-packages/airflow/example_dags/example_branch_labels.py
[2023-08-29 19:36:09,339] {processor.py:641} INFO - Processing file /home/felipe/extracao_dados/venv/lib/python3.9/site-packages/airflow/example_dags/example_branch_labels.py for tasks to queue
[2023-08-29 19:36:09,342] {logging_mixin.py:115} INFO - [2023-08-29 19:36:09,342] {dagbag.py:507} INFO - Filling up the DagBag from /home/felipe/extracao_dados/venv/lib/python3.9/site-packages/airflow/example_dags/example_branch_labels.py
[2023-08-29 19:36:09,583] {processor.py:651} INFO - DAG(s) dict_keys(['example_branch_labels']) retrieved from /home/felipe/extracao_dados/venv/lib/python3.9/site-packages/airflow/example_dags/example_branch_labels.py
[2023-08-29 19:36:10,334] {logging_mixin.py:115} INFO - [2023-08-29 19:36:10,333] {manager.py:508} INFO - Created Permission View: can delete on DAG:example_branch_labels
[2023-08-29 19:36:10,364] {logging_mixin.py:115} INFO - [2023-08-29 19:36:10,363] {manager.py:508} INFO - Created Permission View: can read on DAG:example_branch_labels
[2023-08-29 19:36:10,389] {logging_mixin.py:115} INFO - [2023-08-29 19:36:10,389] {manager.py:508} INFO - Created Permission View: can edit on DAG:example_branch_labels
[2023-08-29 19:36:10,390] {logging_mixin.py:115} INFO - [2023-08-29 19:36:10,389] {dag.py:2379} INFO - Sync 1 DAGs
[2023-08-29 19:36:10,413] {logging_mixin.py:115} INFO - [2023-08-29 19:36:10,412] {dag.py:2398} INFO - Creating ORM DAG for example_branch_labels
[2023-08-29 19:36:10,522] {logging_mixin.py:115} INFO - [2023-08-29 19:36:10,522] {dag.py:2927} INFO - Setting next_dagrun for example_branch_labels to 2023-08-28T00:00:00+00:00, run_after=2023-08-29T00:00:00+00:00
[2023-08-29 19:36:10,804] {logging_mixin.py:115} WARNING - /home/felipe/extracao_dados/venv/lib/python3.9/site-packages/airflow/models/dagbag.py:609 DeprecationWarning: DAG.full_filepath is deprecated in favour of fileloc
[2023-08-29 19:36:10,897] {logging_mixin.py:115} INFO - [2023-08-29 19:36:10,805] {dagbag.py:609} ERROR - Failed to write serialized DAG: /home/felipe/extracao_dados/venv/lib/python3.9/site-packages/airflow/example_dags/example_branch_labels.py
Traceback (most recent call last):
  File "/home/felipe/extracao_dados/venv/lib/python3.9/site-packages/airflow/models/dagbag.py", line 598, in _serialize_dag_capturing_errors
    dag_was_updated = SerializedDagModel.write_dag(
  File "/home/felipe/extracao_dados/venv/lib/python3.9/site-packages/airflow/utils/session.py", line 68, in wrapper
    return func(*args, **kwargs)
  File "/home/felipe/extracao_dados/venv/lib/python3.9/site-packages/airflow/models/serialized_dag.py", line 138, in write_dag
    session.query(literal(True))
  File "/home/felipe/extracao_dados/venv/lib/python3.9/site-packages/sqlalchemy/orm/query.py", line 2734, in first
    return self.limit(1)._iter().first()
  File "/home/felipe/extracao_dados/venv/lib/python3.9/site-packages/sqlalchemy/orm/query.py", line 2818, in _iter
    result = self.session.execute(
  File "/home/felipe/extracao_dados/venv/lib/python3.9/site-packages/sqlalchemy/orm/session.py", line 1669, in execute
    conn = self._connection_for_bind(bind, close_with_result=True)
  File "/home/felipe/extracao_dados/venv/lib/python3.9/site-packages/sqlalchemy/orm/session.py", line 1519, in _connection_for_bind
    return self._transaction._connection_for_bind(
  File "/home/felipe/extracao_dados/venv/lib/python3.9/site-packages/sqlalchemy/orm/session.py", line 721, in _connection_for_bind
    self._assert_active()
  File "/home/felipe/extracao_dados/venv/lib/python3.9/site-packages/sqlalchemy/orm/session.py", line 601, in _assert_active
    raise sa_exc.PendingRollbackError(
sqlalchemy.exc.PendingRollbackError: This Session's transaction has been rolled back due to a previous exception during flush. To begin a new transaction with this Session, first issue Session.rollback(). Original exception was: (sqlite3.DatabaseError) database disk image is malformed
[SQL: INSERT INTO dag_code (fileloc_hash, fileloc, last_updated, source_code) VALUES (?, ?, ?, ?)]
[parameters: (66418591402456362, '/home/felipe/extracao_dados/venv/lib/python3.9/site-packages/airflow/example_dags/example_branch_labels.py', '2023-08-29 22:36:10.528724', '#\n# Licensed to the Apache Software Foundation (ASF) under one\n# or more contributor license agreements.  See the NOTICE file\n# distributed with t ... (1393 characters truncated) ...    ingest >> analyse >> check\n    check >> Label("No errors") >> save >> report\n    check >> Label("Errors found") >> describe >> error >> report\n')]
(Background on this error at: http://sqlalche.me/e/14/4xp6) (Background on this error at: http://sqlalche.me/e/14/7s2a)
[2023-08-29 19:36:10,898] {logging_mixin.py:115} INFO - [2023-08-29 19:36:10,898] {dag.py:2379} INFO - Sync 1 DAGs
[2023-08-29 19:36:10,903] {processor.py:164} ERROR - Got an exception! Propagating...
Traceback (most recent call last):
  File "/home/felipe/extracao_dados/venv/lib/python3.9/site-packages/airflow/dag_processing/processor.py", line 155, in _run_file_processor
    result: Tuple[int, int] = dag_file_processor.process_file(
  File "/home/felipe/extracao_dados/venv/lib/python3.9/site-packages/airflow/utils/session.py", line 71, in wrapper
    return func(*args, session=session, **kwargs)
  File "/home/felipe/extracao_dados/venv/lib/python3.9/site-packages/airflow/dag_processing/processor.py", line 660, in process_file
    dagbag.sync_to_db()
  File "/home/felipe/extracao_dados/venv/lib/python3.9/site-packages/airflow/utils/session.py", line 71, in wrapper
    return func(*args, session=session, **kwargs)
  File "/home/felipe/extracao_dados/venv/lib/python3.9/site-packages/airflow/models/dagbag.py", line 615, in sync_to_db
    for attempt in run_with_db_retries(logger=self.log):
  File "/home/felipe/extracao_dados/venv/lib/python3.9/site-packages/tenacity/__init__.py", line 382, in __iter__
    do = self.iter(retry_state=retry_state)
  File "/home/felipe/extracao_dados/venv/lib/python3.9/site-packages/tenacity/__init__.py", line 349, in iter
    return fut.result()
  File "/usr/lib/python3.9/concurrent/futures/_base.py", line 439, in result
    return self.__get_result()
  File "/usr/lib/python3.9/concurrent/futures/_base.py", line 391, in __get_result
    raise self._exception
  File "/home/felipe/extracao_dados/venv/lib/python3.9/site-packages/airflow/models/dagbag.py", line 629, in sync_to_db
    DAG.bulk_write_to_db(self.dags.values(), session=session)
  File "/home/felipe/extracao_dados/venv/lib/python3.9/site-packages/airflow/utils/session.py", line 68, in wrapper
    return func(*args, **kwargs)
  File "/home/felipe/extracao_dados/venv/lib/python3.9/site-packages/airflow/models/dag.py", line 2387, in bulk_write_to_db
    orm_dags: List[DagModel] = with_row_locks(query, of=DagModel, session=session).all()
  File "/home/felipe/extracao_dados/venv/lib/python3.9/site-packages/sqlalchemy/orm/query.py", line 2683, in all
    return self._iter().all()
  File "/home/felipe/extracao_dados/venv/lib/python3.9/site-packages/sqlalchemy/orm/query.py", line 2818, in _iter
    result = self.session.execute(
  File "/home/felipe/extracao_dados/venv/lib/python3.9/site-packages/sqlalchemy/orm/session.py", line 1669, in execute
    conn = self._connection_for_bind(bind, close_with_result=True)
  File "/home/felipe/extracao_dados/venv/lib/python3.9/site-packages/sqlalchemy/orm/session.py", line 1519, in _connection_for_bind
    return self._transaction._connection_for_bind(
  File "/home/felipe/extracao_dados/venv/lib/python3.9/site-packages/sqlalchemy/orm/session.py", line 721, in _connection_for_bind
    self._assert_active()
  File "/home/felipe/extracao_dados/venv/lib/python3.9/site-packages/sqlalchemy/orm/session.py", line 601, in _assert_active
    raise sa_exc.PendingRollbackError(
sqlalchemy.exc.PendingRollbackError: This Session's transaction has been rolled back due to a previous exception during flush. To begin a new transaction with this Session, first issue Session.rollback(). Original exception was: (sqlite3.DatabaseError) database disk image is malformed
[SQL: INSERT INTO dag_code (fileloc_hash, fileloc, last_updated, source_code) VALUES (?, ?, ?, ?)]
[parameters: (66418591402456362, '/home/felipe/extracao_dados/venv/lib/python3.9/site-packages/airflow/example_dags/example_branch_labels.py', '2023-08-29 22:36:10.528724', '#\n# Licensed to the Apache Software Foundation (ASF) under one\n# or more contributor license agreements.  See the NOTICE file\n# distributed with t ... (1393 characters truncated) ...    ingest >> analyse >> check\n    check >> Label("No errors") >> save >> report\n    check >> Label("Errors found") >> describe >> error >> report\n')]
(Background on this error at: http://sqlalche.me/e/14/4xp6) (Background on this error at: http://sqlalche.me/e/14/7s2a)
